<?xml version="1.0" ?>
<robot name="HIRONXJSK" xmlns:xi="http://www.w3.org/2001/XInclude">
	<link name="WAIST">
		<visual>
			<origin rpy="0 -0 0" xyz="0 0 0"/>
			<geometry>
				<mesh filename="/home/iwata/mujoco-python-viewer/mujoco_ws/src/agent-system/lecture2023/mujoco_tutorials/model/HIRONXJSK_meshes/WAIST_mesh.stl" scale="1 1 1"/>
			</geometry>
		</visual>
		<collision>
			<origin rpy="0 -0 0" xyz="0 0 0"/>
			<geometry>
				<mesh filename="/home/iwata/mujoco-python-viewer/mujoco_ws/src/agent-system/lecture2023/mujoco_tutorials/model/HIRONXJSK_meshes/WAIST_mesh.stl" scale="1 1 1"/>
			</geometry>
		</collision>
		<inertial>
			<mass value="3.11081"/>
			<origin rpy="0 -0 0" xyz="-0.00038809 1.66e-06 0.16466"/>
			<inertia ixx="0.0347318" ixy="5.78001e-06" ixz="-3.34135e-05" iyy="0.0347482" iyz="6.35727e-07" izz="0.00438238"/>
		</inertial>
	</link>
	<gazebo reference="WAIST">
		<mu1>0.9</mu1>
		<mu2>0.9</mu2>
	</gazebo>
	<link name="BASE_TOP">
		<visual>
			<origin rpy="0 -0 0" xyz="0 0 0"/>
			<geometry>
				<mesh filename="/home/iwata/mujoco-python-viewer/mujoco_ws/src/agent-system/lecture2023/mujoco_tutorials/model/HIRONXJSK_meshes/BASE_TOP_mesh.stl" scale="1 1 1"/>
			</geometry>
		</visual>
		<collision>
			<origin rpy="0 -0 0" xyz="0 0 0"/>
			<geometry>
				<mesh filename="/home/iwata/mujoco-python-viewer/mujoco_ws/src/agent-system/lecture2023/mujoco_tutorials/model/HIRONXJSK_meshes/BASE_TOP_mesh.stl" scale="1 1 1"/>
			</geometry>
		</collision>
		<inertial>
			<mass value="25"/>
			<origin rpy="0 -0 0" xyz="0 0 -0.15"/>
			<inertia ixx="20" ixy="0" ixz="0" iyy="20" iyz="0" izz="20"/>
		</inertial>
	</link>
	<gazebo reference="BASE_TOP">
		<mu1>0.9</mu1>
		<mu2>0.9</mu2>
	</gazebo>
	<link name="BASE_BOTTOM">
		<visual>
			<origin rpy="0 -0 0" xyz="0 0 0"/>
			<geometry>
				<mesh filename="/home/iwata/mujoco-python-viewer/mujoco_ws/src/agent-system/lecture2023/mujoco_tutorials/model/HIRONXJSK_meshes/BASE_BOTTOM_mesh.stl" scale="1 1 1"/>
			</geometry>
		</visual>
		<collision>
			<origin rpy="0 -0 0" xyz="0 0 0"/>
			<geometry>
				<mesh filename="/home/iwata/mujoco-python-viewer/mujoco_ws/src/agent-system/lecture2023/mujoco_tutorials/model/HIRONXJSK_meshes/BASE_BOTTOM_mesh.stl" scale="1 1 1"/>
			</geometry>
		</collision>
		<inertial>
			<mass value="75"/>
			<origin rpy="0 -0 0" xyz="0 0 -0.555"/>
			<inertia ixx="20" ixy="0" ixz="0" iyy="20" iyz="0" izz="20"/>
		</inertial>
	</link>
	<gazebo reference="BASE_BOTTOM">
		<mu1>0.9</mu1>
		<mu2>0.9</mu2>
	</gazebo>
	<link name="CHEST_JOINT0_Link">
		<visual>
			<origin rpy="0 -0 0" xyz="0 0 0"/>
			<geometry>
				<mesh filename="/home/iwata/mujoco-python-viewer/mujoco_ws/src/agent-system/lecture2023/mujoco_tutorials/model/HIRONXJSK_meshes/CHEST_JOINT0_Link_mesh.stl" scale="1 1 1"/>
			</geometry>
		</visual>
		<collision>
			<origin rpy="0 -0 0" xyz="0 0 0"/>
			<geometry>
				<mesh filename="/home/iwata/mujoco-python-viewer/mujoco_ws/src/agent-system/lecture2023/mujoco_tutorials/model/HIRONXJSK_meshes/CHEST_JOINT0_Link_mesh.stl" scale="1 1 1"/>
			</geometry>
		</collision>
		<inertial>
			<mass value="6.20761"/>
			<origin rpy="0 -0 0" xyz="-0.00493378 -0.00097682 0.344052"/>
			<inertia ixx="0.0639575" ixy="-0.00022833" ixz="0.00011172" iyy="0.0310845" iyz="6.48e-05" izz="0.0501107"/>
		</inertial>
	</link>
	<gazebo reference="CHEST_JOINT0_Link">
		<mu1>0.9</mu1>
		<mu2>0.9</mu2>
	</gazebo>
	<link name="HEAD_JOINT0_Link">
		<visual>
			<origin rpy="0 -0 0" xyz="0 0 0.5695"/>
			<geometry>
				<mesh filename="/home/iwata/mujoco-python-viewer/mujoco_ws/src/agent-system/lecture2023/mujoco_tutorials/model/HIRONXJSK_meshes/HEAD_JOINT0_Link_mesh.stl" scale="1 1 1"/>
			</geometry>
		</visual>
		<collision>
			<origin rpy="0 -0 0" xyz="0 0 0.5695"/>
			<geometry>
				<mesh filename="/home/iwata/mujoco-python-viewer/mujoco_ws/src/agent-system/lecture2023/mujoco_tutorials/model/HIRONXJSK_meshes/HEAD_JOINT0_Link_mesh.stl" scale="1 1 1"/>
			</geometry>
		</collision>
		<inertial>
			<mass value="0.317929"/>
			<origin rpy="0 -0 0" xyz="-2.292e-05 0.00547848 -0.00784016"/>
			<inertia ixx="0.00027682" ixy="3e-08" ixz="-3.3e-07" iyy="0.00013009" iyz="-1.092e-05" izz="0.00020954"/>
		</inertial>
	</link>
	<gazebo reference="HEAD_JOINT0_Link">
		<mu1>0.9</mu1>
		<mu2>0.9</mu2>
	</gazebo>
	<link name="HEAD_JOINT1_Link">
		<visual>
			<origin rpy="0 -0 0" xyz="0 0 0"/>
			<geometry>
				<mesh filename="/home/iwata/mujoco-python-viewer/mujoco_ws/src/agent-system/lecture2023/mujoco_tutorials/model/HIRONXJSK_meshes/HEAD_JOINT1_Link_mesh.stl" scale="1 1 1"/>
			</geometry>
		</visual>
		<collision>
			<origin rpy="0 -0 0" xyz="0 0 0"/>
			<geometry>
				<mesh filename="/home/iwata/mujoco-python-viewer/mujoco_ws/src/agent-system/lecture2023/mujoco_tutorials/model/HIRONXJSK_meshes/HEAD_JOINT1_Link_mesh.stl" scale="1 1 1"/>
			</geometry>
		</collision>
		<inertial>
			<mass value="0.0808593"/>
			<origin rpy="0 -0 0" xyz="5.02e-06 -0.0166777 0.0163153"/>
			<inertia ixx="1e-03" ixy="0" ixz="0" iyy="1e-03" iyz="0" izz="1e-03"/>
		</inertial>
	</link>
	<gazebo reference="HEAD_JOINT1_Link">
		<mu1>0.9</mu1>
		<mu2>0.9</mu2>
	</gazebo>
	<link name="LARM_JOINT0_Link">
		<visual>
			<origin rpy="-0.261799 0 0" xyz="0 0.145 0.370296"/>
			<geometry>
				<mesh filename="/home/iwata/mujoco-python-viewer/mujoco_ws/src/agent-system/lecture2023/mujoco_tutorials/model/HIRONXJSK_meshes/LARM_JOINT0_Link_mesh.stl" scale="1 1 1"/>
			</geometry>
		</visual>
		<collision>
			<origin rpy="-0.261799 0 0" xyz="0 0.145 0.370296"/>
			<geometry>
				<mesh filename="/home/iwata/mujoco-python-viewer/mujoco_ws/src/agent-system/lecture2023/mujoco_tutorials/model/HIRONXJSK_meshes/LARM_JOINT0_Link_mesh.stl" scale="1 1 1"/>
			</geometry>
		</collision>
		<inertial>
			<mass value="1.32626"/>
			<origin rpy="0 -0 0" xyz="-0.00226388 -0.00521383 0.0156081"/>
			<inertia ixx="0.00207537" ixy="0.00011276" ixz="8.927e-05" iyy="0.00240295" iyz="-4.57e-05" izz="0.00141912"/>
		</inertial>
	</link>
	<gazebo reference="LARM_JOINT0_Link">
		<mu1>0.9</mu1>
		<mu2>0.9</mu2>
	</gazebo>
	<link name="LARM_JOINT1_Link">
		<visual>
			<origin rpy="0 -0 0" xyz="0 0 0"/>
			<geometry>
				<mesh filename="/home/iwata/mujoco-python-viewer/mujoco_ws/src/agent-system/lecture2023/mujoco_tutorials/model/HIRONXJSK_meshes/LARM_JOINT1_Link_mesh.stl" scale="1 1 1"/>
			</geometry>
		</visual>
		<collision>
			<origin rpy="0 -0 0" xyz="0 0 0"/>
			<geometry>
				<mesh filename="/home/iwata/mujoco-python-viewer/mujoco_ws/src/agent-system/lecture2023/mujoco_tutorials/model/HIRONXJSK_meshes/LARM_JOINT1_Link_mesh.stl" scale="1 1 1"/>
			</geometry>
		</collision>
		<inertial>
			<mass value="1.14898"/>
			<origin rpy="0 -0 0" xyz="-5.236e-05 0.0583134 -0.107061"/>
			<inertia ixx="0.0154168" ixy="9.95417e-07" ixz="3.38147e-06" iyy="0.0147117" iyz="0.00213719" izz="0.0012658"/>
		</inertial>
	</link>
	<gazebo reference="LARM_JOINT1_Link">
		<mu1>0.9</mu1>
		<mu2>0.9</mu2>
	</gazebo>
	<link name="LARM_JOINT2_Link">
		<visual>
			<origin rpy="0 -0 0" xyz="0 0.095 -0.25"/>
			<geometry>
				<mesh filename="/home/iwata/mujoco-python-viewer/mujoco_ws/src/agent-system/lecture2023/mujoco_tutorials/model/HIRONXJSK_meshes/LARM_JOINT2_Link_mesh.stl" scale="1 1 1"/>
			</geometry>
		</visual>
		<collision>
			<origin rpy="0 -0 0" xyz="0 0.095 -0.25"/>
			<geometry>
				<mesh filename="/home/iwata/mujoco-python-viewer/mujoco_ws/src/agent-system/lecture2023/mujoco_tutorials/model/HIRONXJSK_meshes/LARM_JOINT2_Link_mesh.stl" scale="1 1 1"/>
			</geometry>
		</collision>
		<inertial>
			<mass value="0.577518"/>
			<origin rpy="0 -0 0" xyz="-2.254e-05 0.00167107 -0.0715116"/>
			<inertia ixx="0.00143966" ixy="-3e-07" ixz="1.2e-06" iyy="0.00141763" iyz="-7.596e-05" izz="0.0001972"/>
		</inertial>
	</link>
	<gazebo reference="LARM_JOINT2_Link">
		<mu1>0.9</mu1>
		<mu2>0.9</mu2>
	</gazebo>
	<link name="LARM_JOINT3_Link">
		<visual>
			<origin rpy="0 -0 0" xyz="-0.03 0 0"/>
			<geometry>
				<mesh filename="/home/iwata/mujoco-python-viewer/mujoco_ws/src/agent-system/lecture2023/mujoco_tutorials/model/HIRONXJSK_meshes/LARM_JOINT3_Link_mesh.stl" scale="1 1 1"/>
			</geometry>
		</visual>
		<collision>
			<origin rpy="0 -0 0" xyz="-0.03 0 0"/>
			<geometry>
				<mesh filename="/home/iwata/mujoco-python-viewer/mujoco_ws/src/agent-system/lecture2023/mujoco_tutorials/model/HIRONXJSK_meshes/LARM_JOINT3_Link_mesh.stl" scale="1 1 1"/>
			</geometry>
		</collision>
		<inertial>
			<mass value="0.457418"/>
			<origin rpy="0 -0 0" xyz="-1.788e-05 -0.00395812 -0.20273"/>
			<inertia ixx="0.00069205" ixy="3e-08" ixz="5.2e-07" iyy="0.00068903" iyz="-1.915e-05" izz="0.00013509"/>
		</inertial>
	</link>
	<gazebo reference="LARM_JOINT3_Link">
		<mu1>0.9</mu1>
		<mu2>0.9</mu2>
	</gazebo>
	<link name="LARM_JOINT4_Link">
		<visual>
			<origin rpy="0 -0 0" xyz="0 0 -0.235"/>
			<geometry>
				<mesh filename="/home/iwata/mujoco-python-viewer/mujoco_ws/src/agent-system/lecture2023/mujoco_tutorials/model/HIRONXJSK_meshes/LARM_JOINT4_Link_mesh.stl" scale="1 1 1"/>
			</geometry>
		</visual>
		<collision>
			<origin rpy="0 -0 0" xyz="0 0 -0.235"/>
			<geometry>
				<mesh filename="/home/iwata/mujoco-python-viewer/mujoco_ws/src/agent-system/lecture2023/mujoco_tutorials/model/HIRONXJSK_meshes/LARM_JOINT4_Link_mesh.stl" scale="1 1 1"/>
			</geometry>
		</collision>
		<inertial>
			<mass value="0.418434"/>
			<origin rpy="0 -0 0" xyz="0.00243131 0.00379733 -0.0577036"/>
			<inertia ixx="0.00052016" ixy="1.69e-06" ixz="7.9e-06" iyy="0.00050569" iyz="-5.377e-05" izz="0.00014004"/>
		</inertial>
	</link>
	<gazebo reference="LARM_JOINT4_Link">
		<mu1>0.9</mu1>
		<mu2>0.9</mu2>
	</gazebo>
	<link name="LARM_JOINT5_Link">
		<visual>
			<origin rpy="0 -0 0" xyz="-0.099 0 -0.09"/>
			<geometry>
				<mesh filename="/home/iwata/mujoco-python-viewer/mujoco_ws/src/agent-system/lecture2023/mujoco_tutorials/model/HIRONXJSK_meshes/LARM_JOINT5_Link_mesh.stl" scale="1 1 1"/>
			</geometry>
		</visual>
		<collision>
			<origin rpy="0 -0 0" xyz="-0.099 0 -0.09"/>
			<geometry>
				<mesh filename="/home/iwata/mujoco-python-viewer/mujoco_ws/src/agent-system/lecture2023/mujoco_tutorials/model/HIRONXJSK_meshes/LARM_JOINT5_Link_mesh.stl" scale="1 1 1"/>
			</geometry>
		</collision>
		<inertial>
			<mass value="1.05156"/>
			<origin rpy="0 -0 0" xyz="-0.048476 -3.2e-06 -0.0388988"/>
			<inertia ixx="0.00194072" ixy="1.1e-07" ixz="-0.00042482" iyy="0.00209392" iyz="1.2e-07" izz="0.00035788"/>
		</inertial>
	</link>
	<gazebo reference="LARM_JOINT5_Link">
		<mu1>0.9</mu1>
		<mu2>0.9</mu2>
	</gazebo>
	<link name="LHAND_JOINT0_Link">
		<visual>
			<origin rpy="0 -0 0" xyz="-0.0299 -0.033 0"/>
			<geometry>
				<mesh filename="/home/iwata/mujoco-python-viewer/mujoco_ws/src/agent-system/lecture2023/mujoco_tutorials/model/HIRONXJSK_meshes/LHAND_JOINT0_Link_mesh.stl" scale="1 1 1"/>
			</geometry>
		</visual>
		<collision>
			<origin rpy="0 -0 0" xyz="-0.0299 -0.033 0"/>
			<geometry>
				<mesh filename="/home/iwata/mujoco-python-viewer/mujoco_ws/src/agent-system/lecture2023/mujoco_tutorials/model/HIRONXJSK_meshes/LHAND_JOINT0_Link_mesh.stl" scale="1 1 1"/>
			</geometry>
		</collision>
		<inertial>
			<mass value="0.01"/>
			<origin rpy="0 -0 0" xyz="0 2.77556e-17 2.77556e-17"/>
			<inertia ixx="1e-03" ixy="0" ixz="0" iyy="1e-03" iyz="0" izz="1e-03"/>
		</inertial>
	</link>
	<gazebo reference="LHAND_JOINT0_Link">
		<mu1>0.9</mu1>
		<mu2>0.9</mu2>
	</gazebo>
	<link name="LHAND_JOINT1_Link">
		<visual>
			<origin rpy="0 -0 0" xyz="-0.0419 0 0"/>
			<geometry>
				<mesh filename="/home/iwata/mujoco-python-viewer/mujoco_ws/src/agent-system/lecture2023/mujoco_tutorials/model/HIRONXJSK_meshes/LHAND_JOINT1_Link_mesh.stl" scale="1 1 1"/>
			</geometry>
		</visual>
		<collision>
			<origin rpy="0 -0 0" xyz="-0.0419 0 0"/>
			<geometry>
				<mesh filename="/home/iwata/mujoco-python-viewer/mujoco_ws/src/agent-system/lecture2023/mujoco_tutorials/model/HIRONXJSK_meshes/LHAND_JOINT1_Link_mesh.stl" scale="1 1 1"/>
			</geometry>
		</collision>
		<inertial>
			<mass value="0.01"/>
			<origin rpy="0 -0 0" xyz="0 2.77556e-17 2.77556e-17"/>
			<inertia ixx="1e-03" ixy="0" ixz="0" iyy="1e-03" iyz="0" izz="1e-03"/>
		</inertial>
	</link>
	<gazebo reference="LHAND_JOINT1_Link">
		<mu1>0.9</mu1>
		<mu2>0.9</mu2>
	</gazebo>
	<link name="LHAND_JOINT2_Link">
		<visual>
			<origin rpy="0 -0 0" xyz="-0.0299 0.033 0"/>
			<geometry>
				<mesh filename="/home/iwata/mujoco-python-viewer/mujoco_ws/src/agent-system/lecture2023/mujoco_tutorials/model/HIRONXJSK_meshes/LHAND_JOINT2_Link_mesh.stl" scale="1 1 1"/>
			</geometry>
		</visual>
		<collision>
			<origin rpy="0 -0 0" xyz="-0.0299 0.033 0"/>
			<geometry>
				<mesh filename="/home/iwata/mujoco-python-viewer/mujoco_ws/src/agent-system/lecture2023/mujoco_tutorials/model/HIRONXJSK_meshes/LHAND_JOINT2_Link_mesh.stl" scale="1 1 1"/>
			</geometry>
		</collision>
		<inertial>
			<mass value="0.01"/>
			<origin rpy="0 -0 0" xyz="0 2.77556e-17 2.77556e-17"/>
			<inertia ixx="1e-03" ixy="0" ixz="0" iyy="1e-03" iyz="0" izz="1e-03"/>
		</inertial>
	</link>
	<gazebo reference="LHAND_JOINT2_Link">
		<mu1>0.9</mu1>
		<mu2>0.9</mu2>
	</gazebo>
	<link name="LHAND_JOINT3_Link">
		<visual>
			<origin rpy="0 -0 0" xyz="-0.0419 0 0"/>
			<geometry>
				<mesh filename="/home/iwata/mujoco-python-viewer/mujoco_ws/src/agent-system/lecture2023/mujoco_tutorials/model/HIRONXJSK_meshes/LHAND_JOINT3_Link_mesh.stl" scale="1 1 1"/>
			</geometry>
		</visual>
		<collision>
			<origin rpy="0 -0 0" xyz="-0.0419 0 0"/>
			<geometry>
				<mesh filename="/home/iwata/mujoco-python-viewer/mujoco_ws/src/agent-system/lecture2023/mujoco_tutorials/model/HIRONXJSK_meshes/LHAND_JOINT3_Link_mesh.stl" scale="1 1 1"/>
			</geometry>
		</collision>
		<inertial>
			<mass value="0.01"/>
			<origin rpy="0 -0 0" xyz="0 2.77556e-17 2.77556e-17"/>
			<inertia ixx="1e-03" ixy="0" ixz="0" iyy="1e-03" iyz="0" izz="1e-03"/>
		</inertial>
	</link>
	<gazebo reference="LHAND_JOINT3_Link">
		<mu1>0.9</mu1>
		<mu2>0.9</mu2>
	</gazebo>
	<link name="RARM_JOINT0_Link">
		<visual>
			<origin rpy="0.261799 -0 0" xyz="0 -0.145 0.370296"/>
			<geometry>
				<mesh filename="/home/iwata/mujoco-python-viewer/mujoco_ws/src/agent-system/lecture2023/mujoco_tutorials/model/HIRONXJSK_meshes/RARM_JOINT0_Link_mesh.stl" scale="1 1 1"/>
			</geometry>
		</visual>
		<collision>
			<origin rpy="0.261799 -0 0" xyz="0 -0.145 0.370296"/>
			<geometry>
				<mesh filename="/home/iwata/mujoco-python-viewer/mujoco_ws/src/agent-system/lecture2023/mujoco_tutorials/model/HIRONXJSK_meshes/RARM_JOINT0_Link_mesh.stl" scale="1 1 1"/>
			</geometry>
		</collision>
		<inertial>
			<mass value="1.32626"/>
			<origin rpy="0 -0 0" xyz="-0.00226388 0.00521383 0.0156081"/>
			<inertia ixx="0.00207537" ixy="-0.00011276" ixz="8.927e-05" iyy="0.00240295" iyz="4.57e-05" izz="0.00141912"/>
		</inertial>
	</link>
	<gazebo reference="RARM_JOINT0_Link">
		<mu1>0.9</mu1>
		<mu2>0.9</mu2>
	</gazebo>
	<link name="RARM_JOINT1_Link">
		<visual>
			<origin rpy="0 -0 0" xyz="0 0 0"/>
			<geometry>
				<mesh filename="/home/iwata/mujoco-python-viewer/mujoco_ws/src/agent-system/lecture2023/mujoco_tutorials/model/HIRONXJSK_meshes/RARM_JOINT1_Link_mesh.stl" scale="1 1 1"/>
			</geometry>
		</visual>
		<collision>
			<origin rpy="0 -0 0" xyz="0 0 0"/>
			<geometry>
				<mesh filename="/home/iwata/mujoco-python-viewer/mujoco_ws/src/agent-system/lecture2023/mujoco_tutorials/model/HIRONXJSK_meshes/RARM_JOINT1_Link_mesh.stl" scale="1 1 1"/>
			</geometry>
		</collision>
		<inertial>
			<mass value="1.14898"/>
			<origin rpy="0 -0 0" xyz="-5.236e-05 -0.0583134 -0.107061"/>
			<inertia ixx="0.0154168" ixy="-9.95417e-07" ixz="3.38147e-06" iyy="0.0147117" iyz="-0.00213719" izz="0.0012658"/>
		</inertial>
	</link>
	<gazebo reference="RARM_JOINT1_Link">
		<mu1>0.9</mu1>
		<mu2>0.9</mu2>
	</gazebo>
	<link name="RARM_JOINT2_Link">
		<visual>
			<origin rpy="0 -0 0" xyz="0 -0.095 -0.25"/>
			<geometry>
				<mesh filename="/home/iwata/mujoco-python-viewer/mujoco_ws/src/agent-system/lecture2023/mujoco_tutorials/model/HIRONXJSK_meshes/RARM_JOINT2_Link_mesh.stl" scale="1 1 1"/>
			</geometry>
		</visual>
		<collision>
			<origin rpy="0 -0 0" xyz="0 -0.095 -0.25"/>
			<geometry>
				<mesh filename="/home/iwata/mujoco-python-viewer/mujoco_ws/src/agent-system/lecture2023/mujoco_tutorials/model/HIRONXJSK_meshes/RARM_JOINT2_Link_mesh.stl" scale="1 1 1"/>
			</geometry>
		</collision>
		<inertial>
			<mass value="0.577518"/>
			<origin rpy="0 -0 0" xyz="-2.254e-05 -0.00167107 -0.0715116"/>
			<inertia ixx="0.00143966" ixy="3e-07" ixz="1.2e-06" iyy="0.00141763" iyz="7.596e-05" izz="0.0001972"/>
		</inertial>
	</link>
	<gazebo reference="RARM_JOINT2_Link">
		<mu1>0.9</mu1>
		<mu2>0.9</mu2>
	</gazebo>
	<link name="RARM_JOINT3_Link">
		<visual>
			<origin rpy="0 -0 0" xyz="-0.03 0 0"/>
			<geometry>
				<mesh filename="/home/iwata/mujoco-python-viewer/mujoco_ws/src/agent-system/lecture2023/mujoco_tutorials/model/HIRONXJSK_meshes/RARM_JOINT3_Link_mesh.stl" scale="1 1 1"/>
			</geometry>
		</visual>
		<collision>
			<origin rpy="0 -0 0" xyz="-0.03 0 0"/>
			<geometry>
				<mesh filename="/home/iwata/mujoco-python-viewer/mujoco_ws/src/agent-system/lecture2023/mujoco_tutorials/model/HIRONXJSK_meshes/RARM_JOINT3_Link_mesh.stl" scale="1 1 1"/>
			</geometry>
		</collision>
		<inertial>
			<mass value="0.457418"/>
			<origin rpy="0 -0 0" xyz="-1.788e-05 0.00395812 -0.20273"/>
			<inertia ixx="0.00069205" ixy="-3e-08" ixz="5.2e-07" iyy="0.00068903" iyz="1.915e-05" izz="0.00013509"/>
		</inertial>
	</link>
	<gazebo reference="RARM_JOINT3_Link">
		<mu1>0.9</mu1>
		<mu2>0.9</mu2>
	</gazebo>
	<link name="RARM_JOINT4_Link">
		<visual>
			<origin rpy="0 -0 0" xyz="0 0 -0.235"/>
			<geometry>
				<mesh filename="/home/iwata/mujoco-python-viewer/mujoco_ws/src/agent-system/lecture2023/mujoco_tutorials/model/HIRONXJSK_meshes/RARM_JOINT4_Link_mesh.stl" scale="1 1 1"/>
			</geometry>
		</visual>
		<collision>
			<origin rpy="0 -0 0" xyz="0 0 -0.235"/>
			<geometry>
				<mesh filename="/home/iwata/mujoco-python-viewer/mujoco_ws/src/agent-system/lecture2023/mujoco_tutorials/model/HIRONXJSK_meshes/RARM_JOINT4_Link_mesh.stl" scale="1 1 1"/>
			</geometry>
		</collision>
		<inertial>
			<mass value="0.418434"/>
			<origin rpy="0 -0 0" xyz="0.00243131 -0.00379733 -0.0577036"/>
			<inertia ixx="0.00052016" ixy="-1.69e-06" ixz="7.9e-06" iyy="0.00050569" iyz="5.377e-05" izz="0.00014004"/>
		</inertial>
	</link>
	<gazebo reference="RARM_JOINT4_Link">
		<mu1>0.9</mu1>
		<mu2>0.9</mu2>
	</gazebo>
	<link name="RARM_JOINT5_Link">
		<visual>
			<origin rpy="0 -0 0" xyz="-0.099 0 -0.09"/>
			<geometry>
				<mesh filename="/home/iwata/mujoco-python-viewer/mujoco_ws/src/agent-system/lecture2023/mujoco_tutorials/model/HIRONXJSK_meshes/RARM_JOINT5_Link_mesh.stl" scale="1 1 1"/>
			</geometry>
		</visual>
		<collision>
			<origin rpy="0 -0 0" xyz="-0.099 0 -0.09"/>
			<geometry>
				<mesh filename="/home/iwata/mujoco-python-viewer/mujoco_ws/src/agent-system/lecture2023/mujoco_tutorials/model/HIRONXJSK_meshes/RARM_JOINT5_Link_mesh.stl" scale="1 1 1"/>
			</geometry>
		</collision>
		<inertial>
			<mass value="1.05156"/>
			<origin rpy="0 -0 0" xyz="-0.048476 3.2e-06 -0.0388988"/>
			<inertia ixx="0.00194072" ixy="-1.1e-07" ixz="-0.00042482" iyy="0.00209392" iyz="-1.2e-07" izz="0.00035788"/>
		</inertial>
	</link>
	<gazebo reference="RARM_JOINT5_Link">
		<mu1>0.9</mu1>
		<mu2>0.9</mu2>
	</gazebo>
	<link name="RHAND_JOINT0_Link">
		<visual>
			<origin rpy="0 -0 0" xyz="-0.0299 -0.033 0"/>
			<geometry>
				<mesh filename="/home/iwata/mujoco-python-viewer/mujoco_ws/src/agent-system/lecture2023/mujoco_tutorials/model/HIRONXJSK_meshes/RHAND_JOINT0_Link_mesh.stl" scale="1 1 1"/>
			</geometry>
		</visual>
		<collision>
			<origin rpy="0 -0 0" xyz="-0.0299 -0.033 0"/>
			<geometry>
				<mesh filename="/home/iwata/mujoco-python-viewer/mujoco_ws/src/agent-system/lecture2023/mujoco_tutorials/model/HIRONXJSK_meshes/RHAND_JOINT0_Link_mesh.stl" scale="1 1 1"/>
			</geometry>
		</collision>
		<inertial>
			<mass value="0.01"/>
			<origin rpy="0 -0 0" xyz="0 -2.77556e-17 2.77556e-17"/>
			<inertia ixx="1e-03" ixy="0" ixz="0" iyy="1e-03" iyz="0" izz="1e-03"/>
		</inertial>
	</link>
	<gazebo reference="RHAND_JOINT0_Link">
		<mu1>0.9</mu1>
		<mu2>0.9</mu2>
	</gazebo>
	<link name="RHAND_JOINT1_Link">
		<visual>
			<origin rpy="0 -0 0" xyz="-0.0419 0 0"/>
			<geometry>
				<mesh filename="/home/iwata/mujoco-python-viewer/mujoco_ws/src/agent-system/lecture2023/mujoco_tutorials/model/HIRONXJSK_meshes/RHAND_JOINT1_Link_mesh.stl" scale="1 1 1"/>
			</geometry>
		</visual>
		<collision>
			<origin rpy="0 -0 0" xyz="-0.0419 0 0"/>
			<geometry>
				<mesh filename="/home/iwata/mujoco-python-viewer/mujoco_ws/src/agent-system/lecture2023/mujoco_tutorials/model/HIRONXJSK_meshes/RHAND_JOINT1_Link_mesh.stl" scale="1 1 1"/>
			</geometry>
		</collision>
		<inertial>
			<mass value="0.01"/>
			<origin rpy="0 -0 0" xyz="0 -2.77556e-17 2.77556e-17"/>
			<inertia ixx="1e-03" ixy="0" ixz="0" iyy="1e-03" iyz="0" izz="1e-03"/>
		</inertial>
	</link>
	<gazebo reference="RHAND_JOINT1_Link">
		<mu1>0.9</mu1>
		<mu2>0.9</mu2>
	</gazebo>
	<link name="RHAND_JOINT2_Link">
		<visual>
			<origin rpy="0 -0 0" xyz="-0.0299 0.033 0"/>
			<geometry>
				<mesh filename="/home/iwata/mujoco-python-viewer/mujoco_ws/src/agent-system/lecture2023/mujoco_tutorials/model/HIRONXJSK_meshes/RHAND_JOINT2_Link_mesh.stl" scale="1 1 1"/>
			</geometry>
		</visual>
		<collision>
			<origin rpy="0 -0 0" xyz="-0.0299 0.033 0"/>
			<geometry>
				<mesh filename="/home/iwata/mujoco-python-viewer/mujoco_ws/src/agent-system/lecture2023/mujoco_tutorials/model/HIRONXJSK_meshes/RHAND_JOINT2_Link_mesh.stl" scale="1 1 1"/>
			</geometry>
		</collision>
		<inertial>
			<mass value="0.01"/>
			<origin rpy="0 -0 0" xyz="0 -2.77556e-17 2.77556e-17"/>
			<inertia ixx="1e-03" ixy="0" ixz="0" iyy="1e-03" iyz="0" izz="1e-03"/>
		</inertial>
	</link>
	<gazebo reference="RHAND_JOINT2_Link">
		<mu1>0.9</mu1>
		<mu2>0.9</mu2>
	</gazebo>
	<link name="RHAND_JOINT3_Link">
		<visual>
			<origin rpy="0 -0 0" xyz="-0.0419 0 0"/>
			<geometry>
				<mesh filename="/home/iwata/mujoco-python-viewer/mujoco_ws/src/agent-system/lecture2023/mujoco_tutorials/model/HIRONXJSK_meshes/RHAND_JOINT3_Link_mesh.stl" scale="1 1 1"/>
			</geometry>
		</visual>
		<collision>
			<origin rpy="0 -0 0" xyz="-0.0419 0 0"/>
			<geometry>
				<mesh filename="/home/iwata/mujoco-python-viewer/mujoco_ws/src/agent-system/lecture2023/mujoco_tutorials/model/HIRONXJSK_meshes/RHAND_JOINT3_Link_mesh.stl" scale="1 1 1"/>
			</geometry>
		</collision>
		<inertial>
			<mass value="0.01"/>
			<origin rpy="0 -0 0" xyz="0 -2.77556e-17 2.77556e-17"/>
			<inertia ixx="1e-03" ixy="0" ixz="0" iyy="1e-03" iyz="0" izz="1e-03"/>
		</inertial>
	</link>
	<gazebo reference="RHAND_JOINT3_Link">
		<mu1>0.9</mu1>
		<mu2>0.9</mu2>
	</gazebo>
	<joint name="BASE_TOP_JOINT" type="fixed">
		<parent link="WAIST"/>
		<child link="BASE_TOP"/>
		<origin rpy="0 -0 0 " xyz="0 0 0"/>
		<axis xyz="0 0 1"/>
		<limit effort="100" lower="0" upper="0" velocity="0.5"/>
		<dynamics damping="0.2" friction="0"/>
	</joint>
	<transmission name="BASE_TOP_JOINT_trans" type="pr2_mechanism_model/SimpleTransmission">
		<actuator name="BASE_TOP_JOINT_motor"/>
		<joint name="BASE_TOP_JOINT"/>
		<mechanicalReduction>1</mechanicalReduction>
	</transmission>
	<gazebo reference="BASE_TOP_JOINT">
		<cfmDamping>0.4</cfmDamping>
	</gazebo>
	<joint name="BASE_BOTTOM_JOINT" type="fixed">
		<parent link="BASE_TOP"/>
		<child link="BASE_BOTTOM"/>
		<origin rpy="0 -0 0 " xyz="0 0 0"/>
		<axis xyz="0 0 1"/>
		<limit effort="100" lower="0" upper="0" velocity="0.5"/>
		<dynamics damping="0.2" friction="0"/>
	</joint>
	<transmission name="BASE_BOTTOM_JOINT_trans" type="pr2_mechanism_model/SimpleTransmission">
		<actuator name="BASE_BOTTOM_JOINT_motor"/>
		<joint name="BASE_BOTTOM_JOINT"/>
		<mechanicalReduction>1</mechanicalReduction>
	</transmission>
	<gazebo reference="BASE_BOTTOM_JOINT">
		<cfmDamping>0.4</cfmDamping>
	</gazebo>
	<joint name="CHEST_JOINT0" type="revolute">
		<parent link="WAIST"/>
		<child link="CHEST_JOINT0_Link"/>
		<origin rpy="0 -0 0 " xyz="0 0 0"/>
		<axis xyz="0 0 1"/>
		<limit effort="100" lower="-2.84489" upper="2.84489" velocity="2.26893"/>
		<dynamics damping="0.2" friction="0"/>
	</joint>
	<gazebo reference="CHEST_JOINT0">
		<cfmDamping>0.4</cfmDamping>
	</gazebo>
	<joint name="HEAD_JOINT0" type="revolute">
		<parent link="CHEST_JOINT0_Link"/>
		<child link="HEAD_JOINT0_Link"/>
		<origin rpy="0 -0 0 " xyz="0 0 0.5695"/>
		<axis xyz="0 0 1"/>
		<limit effort="100" lower="-1.22173" upper="1.22173" velocity="2.61799"/>
		<dynamics damping="0.2" friction="0"/>
	</joint>
	<gazebo reference="HEAD_JOINT0">
		<cfmDamping>0.4</cfmDamping>
	</gazebo>
	<joint name="HEAD_JOINT1" type="revolute">
		<parent link="HEAD_JOINT0_Link"/>
		<child link="HEAD_JOINT1_Link"/>
		<origin rpy="0 -0 0 " xyz="0 0 0"/>
		<axis xyz="0 1 0"/>
		<limit effort="100" lower="-0.349066" upper="1.22173" velocity="4.36332"/>
		<dynamics damping="0.2" friction="0"/>
	</joint>
	<gazebo reference="HEAD_JOINT1">
		<cfmDamping>0.4</cfmDamping>
	</gazebo>
	<joint name="LARM_JOINT0" type="revolute">
		<parent link="CHEST_JOINT0_Link"/>
		<child link="LARM_JOINT0_Link"/>
		<origin rpy="-0.261799 0 0 " xyz="0 0.145 0.370296"/>
		<axis xyz="0 0 1"/>
		<limit effort="150" lower="-1.53589" upper="1.53589" velocity="3.00197"/>
		<dynamics damping="0.2" friction="0"/>
	</joint>
	<gazebo reference="LARM_JOINT0">
		<cfmDamping>0.4</cfmDamping>
	</gazebo>
	<joint name="LARM_JOINT1" type="revolute">
		<parent link="LARM_JOINT0_Link"/>
		<child link="LARM_JOINT1_Link"/>
		<origin rpy="0 -0 0 " xyz="0 0 0"/>
		<axis xyz="0 1 0"/>
		<limit effort="200" lower="-2.44346" upper="1.0472" velocity="2.32129"/>
		<dynamics damping="0.2" friction="0"/>
	</joint>
	<gazebo reference="LARM_JOINT1">
		<cfmDamping>0.4</cfmDamping>
	</gazebo>
	<joint name="LARM_JOINT2" type="revolute">
		<parent link="LARM_JOINT1_Link"/>
		<child link="LARM_JOINT2_Link"/>
		<origin rpy="0 -0 0 " xyz="0 0.095 -0.25"/>
		<axis xyz="0 1 0"/>
		<limit effort="100" lower="-2.75762" upper="0" velocity="3.9968"/>
		<dynamics damping="0.2" friction="0"/>
	</joint>
	<gazebo reference="LARM_JOINT2">
		<cfmDamping>0.4</cfmDamping>
	</gazebo>
	<joint name="LARM_JOINT3" type="revolute">
		<parent link="LARM_JOINT2_Link"/>
		<child link="LARM_JOINT3_Link"/>
		<origin rpy="0 -0 0 " xyz="-0.03 0 0"/>
		<axis xyz="0 0 1"/>
		<limit effort="100" lower="-1.8326" upper="2.87979" velocity="2.61799"/>
		<dynamics damping="0.2" friction="0"/>
	</joint>
	<gazebo reference="LARM_JOINT3">
		<cfmDamping>0.4</cfmDamping>
	</gazebo>
	<joint name="LARM_JOINT4" type="revolute">
		<parent link="LARM_JOINT3_Link"/>
		<child link="LARM_JOINT4_Link"/>
		<origin rpy="0 -0 0 " xyz="0 0 -0.235"/>
		<axis xyz="0 1 0"/>
		<limit effort="100" lower="-1.74533" upper="1.74533" velocity="4.36332"/>
		<dynamics damping="0.2" friction="0"/>
	</joint>
	<gazebo reference="LARM_JOINT4">
		<cfmDamping>0.4</cfmDamping>
	</gazebo>
	<joint name="LARM_JOINT5" type="revolute">
		<parent link="LARM_JOINT4_Link"/>
		<child link="LARM_JOINT5_Link"/>
		<origin rpy="0 -0 0 " xyz="-0.099 0 -0.09"/>
		<axis xyz="1 0 0"/>
		<limit effort="100" lower="-2.84489" upper="2.84489" velocity="5.23599"/>
		<dynamics damping="0.2" friction="0"/>
	</joint>
	<gazebo reference="LARM_JOINT5">
		<cfmDamping>0.4</cfmDamping>
	</gazebo>
	<joint name="LHAND_JOINT0" type="revolute">
		<parent link="LARM_JOINT5_Link"/>
		<child link="LHAND_JOINT0_Link"/>
		<origin rpy="0 -0 0 " xyz="-0.0299 -0.033 0"/>
		<axis xyz="0 0 1"/>
		<limit effort="0.71" lower="-3.1415" upper="3.1415" velocity="31.415"/>
		<dynamics damping="0.2" friction="0"/>
	</joint>
	<gazebo reference="LHAND_JOINT0">
		<cfmDamping>0.4</cfmDamping>
	</gazebo>
	<joint name="LHAND_JOINT1" type="revolute">
		<parent link="LHAND_JOINT0_Link"/>
		<child link="LHAND_JOINT1_Link"/>
		<origin rpy="0 -0 0 " xyz="-0.0419 0 0"/>
		<axis xyz="0 0 1"/>
		<limit effort="0.71" lower="-3.1415" upper="3.1415" velocity="31.415"/>
		<dynamics damping="0.2" friction="0"/>
	</joint>
	<gazebo reference="LHAND_JOINT1">
		<cfmDamping>0.4</cfmDamping>
	</gazebo>
	<joint name="LHAND_JOINT2" type="revolute">
		<parent link="LARM_JOINT5_Link"/>
		<child link="LHAND_JOINT2_Link"/>
		<origin rpy="0 -0 0 " xyz="-0.0299 0.033 0"/>
		<axis xyz="0 0 1"/>
		<limit effort="0.71" lower="-3.1415" upper="3.1415" velocity="31.415"/>
		<dynamics damping="0.2" friction="0"/>
	</joint>
	<gazebo reference="LHAND_JOINT2">
		<cfmDamping>0.4</cfmDamping>
	</gazebo>
	<joint name="LHAND_JOINT3" type="revolute">
		<parent link="LHAND_JOINT2_Link"/>
		<child link="LHAND_JOINT3_Link"/>
		<origin rpy="0 -0 0 " xyz="-0.0419 0 0"/>
		<axis xyz="0 0 1"/>
		<limit effort="0.71" lower="-3.1415" upper="3.1415" velocity="31.415"/>
		<dynamics damping="0.2" friction="0"/>
	</joint>
	<gazebo reference="LHAND_JOINT3">
		<cfmDamping>0.4</cfmDamping>
	</gazebo>
	<joint name="RARM_JOINT0" type="revolute">
		<parent link="CHEST_JOINT0_Link"/>
		<child link="RARM_JOINT0_Link"/>
		<origin rpy="0.261799 -0 0 " xyz="0 -0.145 0.370296"/>
		<axis xyz="0 0 1"/>
		<limit effort="150" lower="-1.53589" upper="1.53589" velocity="3.00197"/>
		<dynamics damping="0.2" friction="0"/>
	</joint>
	<gazebo reference="RARM_JOINT0">
		<cfmDamping>0.4</cfmDamping>
	</gazebo>
	<joint name="RARM_JOINT1" type="revolute">
		<parent link="RARM_JOINT0_Link"/>
		<child link="RARM_JOINT1_Link"/>
		<origin rpy="0 -0 0 " xyz="0 0 0"/>
		<axis xyz="0 1 0"/>
		<limit effort="200" lower="-2.44346" upper="1.0472" velocity="2.32129"/>
		<dynamics damping="0.2" friction="0"/>
	</joint>
	<gazebo reference="RARM_JOINT1">
		<cfmDamping>0.4</cfmDamping>
	</gazebo>
	<joint name="RARM_JOINT2" type="revolute">
		<parent link="RARM_JOINT1_Link"/>
		<child link="RARM_JOINT2_Link"/>
		<origin rpy="0 -0 0 " xyz="0 -0.095 -0.25"/>
		<axis xyz="0 1 0"/>
		<limit effort="100" lower="-2.75762" upper="0" velocity="3.9968"/>
		<dynamics damping="0.2" friction="0"/>
	</joint>
	<gazebo reference="RARM_JOINT2">
		<cfmDamping>0.4</cfmDamping>
	</gazebo>
	<joint name="RARM_JOINT3" type="revolute">
		<parent link="RARM_JOINT2_Link"/>
		<child link="RARM_JOINT3_Link"/>
		<origin rpy="0 -0 0 " xyz="-0.03 0 0"/>
		<axis xyz="0 0 1"/>
		<limit effort="100" lower="-2.87979" upper="1.8326" velocity="2.61799"/>
		<dynamics damping="0.2" friction="0"/>
	</joint>
	<gazebo reference="RARM_JOINT3">
		<cfmDamping>0.4</cfmDamping>
	</gazebo>
	<joint name="RARM_JOINT4" type="revolute">
		<parent link="RARM_JOINT3_Link"/>
		<child link="RARM_JOINT4_Link"/>
		<origin rpy="0 -0 0 " xyz="0 0 -0.235"/>
		<axis xyz="0 1 0"/>
		<limit effort="100" lower="-1.74533" upper="1.74533" velocity="4.36332"/>
		<dynamics damping="0.2" friction="0"/>
	</joint>
	<gazebo reference="RARM_JOINT4">
		<cfmDamping>0.4</cfmDamping>
	</gazebo>
	<joint name="RARM_JOINT5" type="revolute">
		<parent link="RARM_JOINT4_Link"/>
		<child link="RARM_JOINT5_Link"/>
		<origin rpy="0 -0 0 " xyz="-0.099 0 -0.09"/>
		<axis xyz="1 0 0"/>
		<limit effort="100" lower="-2.84489" upper="2.84489" velocity="5.23599"/>
		<dynamics damping="0.2" friction="0"/>
	</joint>
	<gazebo reference="RARM_JOINT5">
		<cfmDamping>0.4</cfmDamping>
	</gazebo>
	<joint name="RHAND_JOINT0" type="revolute">
		<parent link="RARM_JOINT5_Link"/>
		<child link="RHAND_JOINT0_Link"/>
		<origin rpy="0 -0 0 " xyz="-0.0299 -0.033 0"/>
		<axis xyz="0 0 1"/>
		<limit effort="0.71" lower="-3.1415" upper="3.1415" velocity="31.415"/>
		<dynamics damping="0.2" friction="0"/>
	</joint>
	<gazebo reference="RHAND_JOINT0">
		<cfmDamping>0.4</cfmDamping>
	</gazebo>
	<joint name="RHAND_JOINT1" type="revolute">
		<parent link="RHAND_JOINT0_Link"/>
		<child link="RHAND_JOINT1_Link"/>
		<origin rpy="0 -0 0 " xyz="-0.0419 0 0"/>
		<axis xyz="0 0 1"/>
		<limit effort="0.71" lower="-3.1415" upper="3.1415" velocity="31.415"/>
		<dynamics damping="0.2" friction="0"/>
	</joint>
	<gazebo reference="RHAND_JOINT1">
		<cfmDamping>0.4</cfmDamping>
	</gazebo>
	<joint name="RHAND_JOINT2" type="revolute">
		<parent link="RARM_JOINT5_Link"/>
		<child link="RHAND_JOINT2_Link"/>
		<origin rpy="0 -0 0 " xyz="-0.0299 0.033 0"/>
		<axis xyz="0 0 1"/>
		<limit effort="0.71" lower="-3.1415" upper="3.1415" velocity="31.415"/>
		<dynamics damping="0.2" friction="0"/>
	</joint>
	<gazebo reference="RHAND_JOINT2">
		<cfmDamping>0.4</cfmDamping>
	</gazebo>
	<joint name="RHAND_JOINT3" type="revolute">
		<parent link="RHAND_JOINT2_Link"/>
		<child link="RHAND_JOINT3_Link"/>
		<origin rpy="0 -0 0 " xyz="-0.0419 0 0"/>
		<axis xyz="0 0 1"/>
		<limit effort="0.71" lower="-3.1415" upper="3.1415" velocity="31.415"/>
		<dynamics damping="0.2" friction="0"/>
	</joint>
	<gazebo reference="RHAND_JOINT3">
		<cfmDamping>0.4</cfmDamping>
	</gazebo>
	<joint name="lhsensor_joint" type="fixed">
		<origin rpy="1.570657 -0.525627 1.570657" xyz="0 0 0"/>
		<parent link="LARM_JOINT5_Link"/>
		<child link="lhsensor"/>
	</joint>
	<link name="lhsensor"/>
	<joint name="rhsensor_joint" type="fixed">
		<origin rpy="1.570808 -0.000012 1.570773" xyz="0 0 0"/>
		<parent link="RARM_JOINT5_Link"/>
		<child link="rhsensor"/>
	</joint>
	<link name="rhsensor"/>
	<joint name="head_camera_link_joint" type="fixed">
		<origin rpy="0.014481 0.009844 -0.009764" xyz="0.0462217 0.0003605 0.0872724"/>
		<parent link="HEAD_JOINT1_Link"/>
		<child link="head_camera_link"/>
	</joint>
	<link name="head_camera_link"/>
	<joint name="head_camera_rgb_frame_joint" type="fixed">
		<origin rpy="0.000000 -0.000000 0.000000" xyz="0 0.02 0"/>
		<parent link="head_camera_link"/>
		<child link="head_camera_rgb_frame"/>
	</joint>
	<link name="head_camera_rgb_frame"/>
	<joint name="head_camera_rgb_optical_frame_joint" type="fixed">
		<origin rpy="-1.570796 0.000000 -1.570796" xyz="0 0 0"/>
		<parent link="head_camera_rgb_frame"/>
		<child link="head_camera_rgb_optical_frame"/>
	</joint>
	<link name="head_camera_rgb_optical_frame"/>
	<joint name="head_camera_depth_frame_joint" type="fixed">
		<origin rpy="0.000000 -0.000000 0.000000" xyz="0 0.045 0"/>
		<parent link="head_camera_link"/>
		<child link="head_camera_depth_frame"/>
	</joint>
	<link name="head_camera_depth_frame"/>
	<joint name="head_camera_depth_optical_frame_joint" type="fixed">
		<origin rpy="-1.570796 0.000000 -1.570796" xyz="0 0 0"/>
		<parent link="head_camera_depth_frame"/>
		<child link="head_camera_depth_optical_frame"/>
	</joint>
	<link name="head_camera_depth_optical_frame"/>
	<joint name="rarm_end_coords_joint" type="fixed">
		<origin rpy="-0.000000 1.570796 0.000000" xyz="-0.05 0 0"/>
		<parent link="RARM_JOINT5_Link"/>
		<child link="rarm_end_coords"/>
	</joint>
	<link name="rarm_end_coords"/>
	<joint name="larm_end_coords_joint" type="fixed">
		<origin rpy="-0.000000 1.570796 0.000000" xyz="-0.05 0 0"/>
		<parent link="LARM_JOINT5_Link"/>
		<child link="larm_end_coords"/>
	</joint>
	<link name="larm_end_coords"/>
	<joint name="head_end_coords_joint" type="fixed">
		<origin rpy="-0.000000 1.570796 0.000000" xyz="0.1 0 0.1"/>
		<parent link="HEAD_JOINT1_Link"/>
		<child link="head_end_coords"/>
	</joint>
	<link name="head_end_coords"/>
	<transmission name="CHEST_JOINT0_trans">
		<type>transmission_interface/SimpleTransmission</type>
		<joint name="CHEST_JOINT0">
			<hardwareInterface>EffortJointInterface</hardwareInterface>
		</joint>
		<actuator name="CHEST_JOINT0_motor">
			<hardwareInterface>EffortJointInterface</hardwareInterface>
			<mechanicalReduction>1</mechanicalReduction>
		</actuator>
	</transmission>
	<transmission name="HEAD_JOINT0_trans">
		<type>transmission_interface/SimpleTransmission</type>
		<joint name="HEAD_JOINT0">
			<hardwareInterface>EffortJointInterface</hardwareInterface>
		</joint>
		<actuator name="HEAD_JOINT0_motor">
			<hardwareInterface>EffortJointInterface</hardwareInterface>
			<mechanicalReduction>1</mechanicalReduction>
		</actuator>
	</transmission>
	<transmission name="HEAD_JOINT1_trans">
		<type>transmission_interface/SimpleTransmission</type>
		<joint name="HEAD_JOINT1">
			<hardwareInterface>EffortJointInterface</hardwareInterface>
		</joint>
		<actuator name="HEAD_JOINT1_motor">
			<hardwareInterface>EffortJointInterface</hardwareInterface>
			<mechanicalReduction>1</mechanicalReduction>
		</actuator>
	</transmission>
	<transmission name="LARM_JOINT0_trans">
		<type>transmission_interface/SimpleTransmission</type>
		<joint name="LARM_JOINT0">
			<hardwareInterface>EffortJointInterface</hardwareInterface>
		</joint>
		<actuator name="LARM_JOINT0_motor">
			<hardwareInterface>EffortJointInterface</hardwareInterface>
			<mechanicalReduction>1</mechanicalReduction>
		</actuator>
	</transmission>
	<transmission name="LARM_JOINT1_trans">
		<type>transmission_interface/SimpleTransmission</type>
		<joint name="LARM_JOINT1">
			<hardwareInterface>EffortJointInterface</hardwareInterface>
		</joint>
		<actuator name="LARM_JOINT1_motor">
			<hardwareInterface>EffortJointInterface</hardwareInterface>
			<mechanicalReduction>1</mechanicalReduction>
		</actuator>
	</transmission>
	<transmission name="LARM_JOINT2_trans">
		<type>transmission_interface/SimpleTransmission</type>
		<joint name="LARM_JOINT2">
			<hardwareInterface>EffortJointInterface</hardwareInterface>
		</joint>
		<actuator name="LARM_JOINT2_motor">
			<hardwareInterface>EffortJointInterface</hardwareInterface>
			<mechanicalReduction>1</mechanicalReduction>
		</actuator>
	</transmission>
	<transmission name="LARM_JOINT3_trans">
		<type>transmission_interface/SimpleTransmission</type>
		<joint name="LARM_JOINT3">
			<hardwareInterface>EffortJointInterface</hardwareInterface>
		</joint>
		<actuator name="LARM_JOINT3_motor">
			<hardwareInterface>EffortJointInterface</hardwareInterface>
			<mechanicalReduction>1</mechanicalReduction>
		</actuator>
	</transmission>
	<transmission name="LARM_JOINT4_trans">
		<type>transmission_interface/SimpleTransmission</type>
		<joint name="LARM_JOINT4">
			<hardwareInterface>EffortJointInterface</hardwareInterface>
		</joint>
		<actuator name="LARM_JOINT4_motor">
			<hardwareInterface>EffortJointInterface</hardwareInterface>
			<mechanicalReduction>1</mechanicalReduction>
		</actuator>
	</transmission>
	<transmission name="LARM_JOINT5_trans">
		<type>transmission_interface/SimpleTransmission</type>
		<joint name="LARM_JOINT5">
			<hardwareInterface>EffortJointInterface</hardwareInterface>
		</joint>
		<actuator name="LARM_JOINT5_motor">
			<hardwareInterface>EffortJointInterface</hardwareInterface>
			<mechanicalReduction>1</mechanicalReduction>
		</actuator>
	</transmission>
	<transmission name="LHAND_JOINT0_trans">
		<type>transmission_interface/SimpleTransmission</type>
		<joint name="LHAND_JOINT0">
			<hardwareInterface>EffortJointInterface</hardwareInterface>
		</joint>
		<actuator name="LHAND_JOINT0_motor">
			<hardwareInterface>EffortJointInterface</hardwareInterface>
			<mechanicalReduction>1</mechanicalReduction>
		</actuator>
	</transmission>
	<transmission name="LHAND_JOINT1_trans">
		<type>transmission_interface/SimpleTransmission</type>
		<joint name="LHAND_JOINT1">
			<hardwareInterface>EffortJointInterface</hardwareInterface>
		</joint>
		<actuator name="LHAND_JOINT1_motor">
			<hardwareInterface>EffortJointInterface</hardwareInterface>
			<mechanicalReduction>1</mechanicalReduction>
		</actuator>
	</transmission>
	<transmission name="LHAND_JOINT2_trans">
		<type>transmission_interface/SimpleTransmission</type>
		<joint name="LHAND_JOINT2">
			<hardwareInterface>EffortJointInterface</hardwareInterface>
		</joint>
		<actuator name="LHAND_JOINT2_motor">
			<hardwareInterface>EffortJointInterface</hardwareInterface>
			<mechanicalReduction>1</mechanicalReduction>
		</actuator>
	</transmission>
	<transmission name="LHAND_JOINT3_trans">
		<type>transmission_interface/SimpleTransmission</type>
		<joint name="LHAND_JOINT3">
			<hardwareInterface>EffortJointInterface</hardwareInterface>
		</joint>
		<actuator name="LHAND_JOINT3_motor">
			<hardwareInterface>EffortJointInterface</hardwareInterface>
			<mechanicalReduction>1</mechanicalReduction>
		</actuator>
	</transmission>
	<transmission name="RARM_JOINT0_trans">
		<type>transmission_interface/SimpleTransmission</type>
		<joint name="RARM_JOINT0">
			<hardwareInterface>EffortJointInterface</hardwareInterface>
		</joint>
		<actuator name="RARM_JOINT0_motor">
			<hardwareInterface>EffortJointInterface</hardwareInterface>
			<mechanicalReduction>1</mechanicalReduction>
		</actuator>
	</transmission>
	<transmission name="RARM_JOINT1_trans">
		<type>transmission_interface/SimpleTransmission</type>
		<joint name="RARM_JOINT1">
			<hardwareInterface>EffortJointInterface</hardwareInterface>
		</joint>
		<actuator name="RARM_JOINT1_motor">
			<hardwareInterface>EffortJointInterface</hardwareInterface>
			<mechanicalReduction>1</mechanicalReduction>
		</actuator>
	</transmission>
	<transmission name="RARM_JOINT2_trans">
		<type>transmission_interface/SimpleTransmission</type>
		<joint name="RARM_JOINT2">
			<hardwareInterface>EffortJointInterface</hardwareInterface>
		</joint>
		<actuator name="RARM_JOINT2_motor">
			<hardwareInterface>EffortJointInterface</hardwareInterface>
			<mechanicalReduction>1</mechanicalReduction>
		</actuator>
	</transmission>
	<transmission name="RARM_JOINT3_trans">
		<type>transmission_interface/SimpleTransmission</type>
		<joint name="RARM_JOINT3">
			<hardwareInterface>EffortJointInterface</hardwareInterface>
		</joint>
		<actuator name="RARM_JOINT3_motor">
			<hardwareInterface>EffortJointInterface</hardwareInterface>
			<mechanicalReduction>1</mechanicalReduction>
		</actuator>
	</transmission>
	<transmission name="RARM_JOINT4_trans">
		<type>transmission_interface/SimpleTransmission</type>
		<joint name="RARM_JOINT4">
			<hardwareInterface>EffortJointInterface</hardwareInterface>
		</joint>
		<actuator name="RARM_JOINT4_motor">
			<hardwareInterface>EffortJointInterface</hardwareInterface>
			<mechanicalReduction>1</mechanicalReduction>
		</actuator>
	</transmission>
	<transmission name="RARM_JOINT5_trans">
		<type>transmission_interface/SimpleTransmission</type>
		<joint name="RARM_JOINT5">
			<hardwareInterface>EffortJointInterface</hardwareInterface>
		</joint>
		<actuator name="RARM_JOINT5_motor">
			<hardwareInterface>EffortJointInterface</hardwareInterface>
			<mechanicalReduction>1</mechanicalReduction>
		</actuator>
	</transmission>
	<transmission name="RHAND_JOINT0_trans">
		<type>transmission_interface/SimpleTransmission</type>
		<joint name="RHAND_JOINT0">
			<hardwareInterface>EffortJointInterface</hardwareInterface>
		</joint>
		<actuator name="RHAND_JOINT0_motor">
			<hardwareInterface>EffortJointInterface</hardwareInterface>
			<mechanicalReduction>1</mechanicalReduction>
		</actuator>
	</transmission>
	<transmission name="RHAND_JOINT1_trans">
		<type>transmission_interface/SimpleTransmission</type>
		<joint name="RHAND_JOINT1">
			<hardwareInterface>EffortJointInterface</hardwareInterface>
		</joint>
		<actuator name="RHAND_JOINT1_motor">
			<hardwareInterface>EffortJointInterface</hardwareInterface>
			<mechanicalReduction>1</mechanicalReduction>
		</actuator>
	</transmission>
	<transmission name="RHAND_JOINT2_trans">
		<type>transmission_interface/SimpleTransmission</type>
		<joint name="RHAND_JOINT2">
			<hardwareInterface>EffortJointInterface</hardwareInterface>
		</joint>
		<actuator name="RHAND_JOINT2_motor">
			<hardwareInterface>EffortJointInterface</hardwareInterface>
			<mechanicalReduction>1</mechanicalReduction>
		</actuator>
	</transmission>
	<transmission name="RHAND_JOINT3_trans">
		<type>transmission_interface/SimpleTransmission</type>
		<joint name="RHAND_JOINT3">
			<hardwareInterface>EffortJointInterface</hardwareInterface>
		</joint>
		<actuator name="RHAND_JOINT3_motor">
			<hardwareInterface>EffortJointInterface</hardwareInterface>
			<mechanicalReduction>1</mechanicalReduction>
		</actuator>
	</transmission>
</robot>
